Workbook

Sheet Datos
B3: Metodo de pago | D3: semana | F3: Dia | I3: Base de Datos (Clientes, Proveedores y Terceros | K3: Gastos
B4: Transferencia | D4: semana 3 | F4: 46157 | I4: Nicolle | K4: Impresión de etiquetas
B5: Efectivo | D5: semana 4 | F5: 46158 | I5: Alexandra | K5: Honorarios y Prestacion de Servicio
B6: Credito | D6: semana 5 | F6: 46159 | I6: Tomas | K6: Gastos por arriendos
B7: Tarjeta | D7: semana 6 | F7: 46160 | I7: Sthepany | K7: Gastos por seguros
D8: semana 7 | F8: 46161 | I8: Gerson | K8: Gastos por servicios
D9: semana 8 | F9: 46162 | I9: Keren | K9: Gastos Legales
D10: semana 9 | F10: 46163 | I10: Cliente Activación | K10: Gasto de Mantenimiento y Reparaciones
D11: semana 10 | F11: 46164 | I11: Cliente Feria | K11: Gastos de viajes
D12: semana 11 | F12: 46165 | I12: Cliente lanzamiento | K12: Otros Gastos
D13: semana 12 | F13: 46166 | I13: Ingris G. negocios | K13: Gastos Bancarios
F14: 46167 | I14: Evelyn Andino | K14: Gastos por interes
F15: 46168 | I15: Fanys Moreno | K15: Otros Gastos Financieros
F16: 46169 | I16: Emely G. negocios | K16: Impuesto de Renta
F17: 46170 | I17: Melissa Canaca | K17: Otros impuestos
F18: 46171 | I18: Fabiola Romero
F19: 46172 | I19: Dilcia UNAH
F20: 46173 | I20: Olman Alvares
F21: 46174 | I21: Sharon Raudales
F22: 46175 | I22: Lic Cesar | K22: Articulos Inventarios
F23: 46176 | I23: David Castillo | K23: Pica extremo
F24: 46177 | I24: Hever Perdomo | K24: Pica rico
F25: 46178 | I25: Francisco Abularach | K25: Pica suave
F26: 46179 | I26: Dionicio Indufesa
F27: 46180 | I27: Obed Sanchez
F28: 46181 | I28: Lamber Giron
F29: 46182 | I29: Bryan Cruz
F30: 46183 | I30: Roberto Ferrera
F31: 46184 | I31: Ramon Cabrera
F32: 46185 | I32: Nelson Cabrera
F33: 46186 | I33: Exon Sierra
F34: 46187 | I34: Consumidor Final
F35: 46188 | I35: Carlos Josiel Hernadez
F36: 46189 | I36: Melvin indufesa
F37: 46190 | I37: estefany meza
... F43: 46196 | I43: Franklin Paredes
F44: 46197
F45: 46198
F46: 46199
F47: 46200
...

Sheet Product
B3: Productos
B4: Item | C4: Nombre | D4: Precio V. Unitario
B5: 1 | C5: =Datos!K23 -> Pica extremo | D5: 130
B6: 2 | C6: =Datos!K24 -> Pica rico | D6: 130
B7: 3 | C7: =Datos!K25 -> Pica suave | D7: 130
B8: 4 | C8: Combo | D8: 180
B9: 5 | C9: pica extremo pequeño | D9: 70
B10: 6 | C10: pica rico pequeño | D10: 70
B11: 7 | C11: pica suave pequeño | D11: 70

Sheet Venta
B2: LIBRO DE VENTAS
B3: Semana | C3: Dia | D3: Cliente | E3: Vendedor | F3: Producto/Servicio | G3: Valor Unitario | H3: Cantidad | I3: Valor total | J3: Forma de Pago | K3: Observaciones | L3: Canal de venta
B4: semana 3 | C4: 46168 | D4: Cliente lanzamiento | F4: Pica extremo | G4: =SUMIFS(Product!$D$5:$D$24,Product!$C$5:$C$24,Venta!F4) -> 130 | H4: 6 | I4: =G4*H4 -> 780 | J4: efectivo
B5: semana 3 | C5: 46168 | D5: Cliente lanzamiento | F5: Pica extremo | G5: =SUMIFS(Product!$D$5:$D$24,Product!$C$5:$C$24,Venta!F5) -> 130 | H5: 9 | I5: =G5*H5 -> 1170 | J5: Transferencia
B6: semana 3 | C6: 46168 | D6: Cliente lanzamiento | F6: Pica rico | G6: =SUMIFS(Product!$D$5:$D$24,Product!$C$5:$C$24,Venta!F6) -> 130 | H6: 4 | I6: =G6*H6 -> 520 | J6: efectivo
B7: semana 3 | C7: 46168 | D7: Cliente lanzamiento | F7: Pica rico | G7: =SUMIFS(Product!$D$5:$D$24,Product!$C$5:$C$24,Venta!F7) -> 130 | H7: 6 | I7: =G7*H7 -> 780 | J7: Transferencia
B8: semana 3 | C8: 46168 | D8: Cliente lanzamiento | F8: Pica suave | G8: =SUMIFS(Product!$D$5:$D$24,Product!$C$5:$C$24,Venta!F8) -> 130 | H8: 1 | I8: =G8*H8 -> 130 | J8: efectivo | M8: TOTAL LANZAMIENTO
B9: semana 3 | C9: 46168 | D9: Cliente lanzamiento | F9: Pica suave | G9: =SUMIFS(Product!$D$5:$D$24,Product!$C$5:$C$24,Venta!F9) -> 130 | H9: 3 | I9: =G9*H9 -> 390 | J9: Transferencia | M9: =SUM(H4:H9) -> 29
B10: semana 3 | C10: 46169 | D10: dilcia unah | E10: keren | F10: Pica extremo | G10: =SUMIFS(Product!$D$5:$D$24,Product!$C$5:$C$24,Venta!F15) -> 130 | H10: 1 | I10: =G10*H10 -> 130 | J10: efectivo | L10: Directo
B11: semana 3 | C11: 46169 | E11: keren | F11: pica suave | G11: =SUMIFS(Product!$D$5:$D$24,Product!$C$5:$C$24,Venta!F20) -> 130 | H11: 1 | I11: =G11*H11 -> 130 | J11: efectivo | L11: Directo
B12: semana 3 | C12: 46169 | D12: Evelyn Andino | E12: Nicolle | F12: Pica extremo | G12: =SUMIFS(Product!$D$5:$D$24,Product!$C$5:$C$24,Venta!F12) -> 130 | H12: 1 | I12: =G12*H12 -> 130 | J12: Transferencia | L12: Directo
B13: semana 3 | C13: 46169 | D13: Nicolle | E13: Nicolle | F13: Pica extremo | G13: =SUMIFS(Product!$D$5:$D$24,Product!$C$5:$C$24,Venta!F14) -> 130 | H13: 1 | I13: =G13*H13 -> 130 | J13: Transferencia | L13: Directo
B14: semana 3 | C14: 46169 | D14: fabiola romero | E14: Nicolle | F14: Pica extremo | G14: =SUMIFS(Product!$D$5:$D$24,Product!$C$5:$C$24,Venta!F16) -> 130 | H14: 1 | I14: =G14*H14 -> 130 | J14: Transferencia | L14: Directo
B15: semana 3 | C15: 46169 | D15: lic cesar | E15: Nicolle | F15: Pica extremo | G15: =SUMIFS(Product!$D$5:$D$24,Product!$C$5:$C$24,Venta!F21) -> 130 | H15: 1 | I15: =G15*H15 -> 130 | J15: efectivo | L15: Directo
B16: semana 3 | C16: 46169 | D16: David Castillo | E16: Nicolle | F16: Pica extremo | G16: =SUMIFS(Product!$D$5:$D$24,Product!$C$5:$C$24,Venta!F22) -> 130 | H16: 2 | I16: =G16*H16 -> 260 | J16: efectivo | L16: Directo
B17: semana 3 | C17: 46169 | D17: sthepany | E17: sthepany | F17: Pica rico | G17: =SUMIFS(Product!$D$5:$D$24,Product!$C$5:$C$24,Venta!F18) -> 130 | H17: 1 | I17: =G17*H17 -> 130 | J17: efectivo | L17: Directo
B18: semana 3 | C18: 46169 | D18: Ingris G. negocios | E18: Nicolle | F18: Pica rico | G18: =SUMIFS(Product!$D$5:$D$24,Product!$C$5:$C$24,Venta!F10) -> 130 | H18: 1 | I18: =G18*H18 -> 130 | J18: efectivo | L18: Directo
B19: semana 3 | C19: 46169 | D19: Emely G. negocios | E19: Nicolle | F19: Pica rico | G19: =SUMIFS(Product!$D$5:$D$24,Product!$C$5:$C$24,Venta!F11) -> 130 | H19: 1 | I19: =G19*H19 -> 130 | J19: efectivo | L19: Directo
B20: semana 3 | C20: 46169 | D20: Fanys Moreno | E20: Nicolle | F20: Pica rico | G20: =SUMIFS(Product!$D$5:$D$24,Product!$C$5:$C$24,Venta!F13) -> 130 | H20: 1 | I20: =G20*H20 -> 130 | J20: Transferencia | L20: Directo
B21: semana 3 | C21: 46169 | D21: olman alvares | E21: Keren | F21: Pica suave | G21: =SUMIFS(Product!$D$5:$D$24,Product!$C$5:$C$24,Venta!F17) -> 130 | H21: 1 | I21: =G21*H21 -> 130 | J21: efectivo | L21: Directo
B22: semana 3 | C22: 46169 | D22: melissa canaca | E22: Nicolle | F22: Pica suave | G22: =SUMIFS(Product!$D$5:$D$24,Product!$C$5:$C$24,Venta!F19) -> 130 | H22: 1 | I22: =G22*H22 -> 130 | J22: Transferencia | L22: Directo
B23: semana 3 | C23: 46170 | D23: francisco abularach | E23: Nicolle | F23: Pica extremo | G23: =SUMIFS(Product!$D$5:$D$24,Product!$C$5:$C$24,Venta!F23) -> 130 | H23: 1 | I23: =G23*H23 -> 130 | J23: efectivo | L23: Directo
B24: semana 3 | C24: 46170 | D24: dionicio indufesa | E24: Nicolle | F24: Pica extremo | G24: =SUMIFS(Product!$D$5:$D$24,Product!$C$5:$C$24,Venta!F24) -> 130 | H24: 1 | I24: =G24*H24 -> 130 | J24: efectivo | L24: Directo
B25: semana 3 | C25: 46170 | D25: obed sanchez | E25: Nicolle | F25: Pica extremo | G25: =SUMIFS(Product!$D$5:$D$24,Product!$C$5:$C$24,Venta!F25) -> 130 | H25: 1 | I25: =G25*H25 -> 130 | J25: efectivo | L25: Directo
B26: semana 3 | C26: 46170 | D26: Lamber Giron | E26: Nicolle | F26: Pica extremo | G26: =SUMIFS(Product!$D$5:$D$24,Product!$C$5:$C$24,Venta!F26) -> 130 | H26: 1 | I26: =G26*H26 -> 130 | J26: Transferencia | L26: Directo
B27: semana 3 | C27: 46170 | D27: hever perdomo | E27: Nicolle | F27: Pica extremo | G27: =SUMIFS(Product!$D$5:$D$24,Product!$C$5:$C$24,Venta!F26) -> 130 | H27: 2 | I27: =G27*H27 -> 260 | J27: Transferencia | L27: Directo
B28: semana 3 | C28: 46170 | D28: Consumidor Final | E28: Alexandra | F28: Pica suave | G28: =SUMIFS(Product!$D$5:$D$24,Product!$C$5:$C$24,Venta!F29) -> 130 | H28: 5 | I28: =G28*H28 -> 650 | J28: efectivo | L28: Directo
B29: semana 3 | C29: 46170 | D29: Consumidor Final | E29: Alexandra | F29: Pica rico | G29: =SUMIFS(Product!$D$5:$D$24,Product!$C$5:$C$24,Venta!F30) -> 130 | H29: 6 | I29: =G29*H29 -> 780 | J29: Transferencia | L29: Directo
B30: semana 3 | C30: 46170 | D30: Consumidor Final | E30: Alexandra | F30: Pica extremo | G30: =SUMIFS(Product!$D$5:$D$24,Product!$C$5:$C$24,Venta!F31) -> 130 | H30: 6 | I30: =G30*H30 -> 780 | J30: Transferencia | L30: Directo
B31: semana 3 | C31: 46170 | D31: David Castillo | E31: Nicolle | F31: Pica rico | G31: =SUMIFS(Product!$D$5:$D$24,Product!$C$5:$C$24,Venta!F28) -> 130 | H31: 1 | I31: =G31*H31 -> 130 | J31: Transferencia | L31: Directo
B32: semana 3 | C32: 46170 | D32: bryan cruz | E32: Tomas | F32: Pica extremo | G32: =SUMIFS(Product!$D$5:$D$24,Product!$C$5:$C$24,Venta!F33) -> 130 | H32: 1 | I32: =G32*H32 -> 130 | J32: Transferencia | L32: Directo
B33: semana 3 | C33: 46170 | D33: David Castillo | E33: Nicolle | F33: Pica suave | G33: =SUMIFS(Product!$D$5:$D$24,Product!$C$5:$C$24,Venta!F27) -> 130 | H33: 2 | I33: =G33*H33 -> 260 | J33: Transferencia | L33: Directo
B34: semana 3 | C34: 46171 | D34: roberto ferrera | E34: Nicolle | F34: Pica extremo | G34: =SUMIFS(Product!$D$5:$D$24,Product!$C$5:$C$24,Venta!F34) -> 130 | H34: 1 | I34: =G34*H34 -> 130 | J34: Transferencia | L34: Directo
B35: semana 3 | C35: 46171 | D35: Consumidor Final | E35: Gerson | F35: Pica rico | G35: =SUMIFS(Product!$D$5:$D$24,Product!$C$5:$C$24,Venta!F37) -> 130 | H35: 1 | I35: =G35*H35 -> 130 | J35: Transferencia | L35: Directo
B36: semana 3 | C36: 46171 | D36: Ramon Cabrera | E36: Tomas | F36: Pica extremo | G36: =SUMIFS(Product!$D$5:$D$24,Product!$C$5:$C$24,Venta!F35) -> 130 | H36: 1 | I36: =G36*H36 -> 130 | J36: Transferencia | L36: Directo
B37: semana 3 | C37: 46171 | D37: Nelson Cabrera | E37: Tomas | F37: Pica extremo | G37: =SUMIFS(Product!$D$5:$D$24,Product!$C$5:$C$24,Venta!F36) -> 130 | H37: 1 | I37: =G37*H37 -> 130 | J37: Transferencia | L37: Directo
B38: semana 3 | C38: 46172 | D38: Sthepany | E38: Sthepany | F38: Pica extremo | G38: =SUMIFS(Product!$D$5:$D$24,Product!$C$5:$C$24,Venta!F38) -> 130 | H38: 5 | I38: =G38*H38 -> 650 | J38: Transferencia | L38: Directo
B39: semana 3 | C39: 46172 | D39: Exon Sierra | E39: Tomas | F39: pica suave | G39: =SUMIFS(Product!$D$5:$D$24,Product!$C$5:$C$24,Venta!F39) -> 130 | H39: 1 | I39: =G39*H39 -> 130 | J39: Transferencia | L39: Directo
B40: semana 4 | C40: 46175 | D40: Consumidor Final | E40: tomas | F40: Pica extremo | G40: =SUMIFS(Product!$D$5:$D$24,Product!$C$5:$C$24,Venta!F41) -> 130 | H40: 1 | I40: =G40*H40 -> 130 | J40: Transferencia | L40: Directo
B41: semana 4 | C41: 46176 | D41: Consumidor Final | E41: Tomas | F41: Pica extremo | G41: =SUMIFS(Product!$D$5:$D$24,Product!$C$5:$C$24,Venta!F65) -> 130 | H41: 1 | I41: =G41*H41 -> 130 | J41: efectivo | L41: Directo
...

Sheet Venta Semana
B1: INFORME DE VENTAS POR PRODUCTO UNIDADES
B2: Item | C2: Producto | D2: Semana 3 | E2: Semana 4 | F2: semana 5 | G2: Semana 6 | H2: Semana 7 | I2: Semana 8 | J2: Semana 9 | K2: Semana 10 | L2: Semana 11 | M2: Semana 12 | N2: Total
B3: 1 | C3: =Product!C5 -> Pica extremo | D3: =SUMIFS(Venta!$I$4:$I$365,Venta!$F$4:$F$365,'Venta Semana'!C3,Venta!$B$4:$B$365,'Venta Semana'!$D$2)/(130) -> 43 | E3: =SUMIFS(Venta!$I$4:$I$365,Venta!$F$4:$F$365,'Venta Semana'!C3,Venta!$B$4:$B$365,'Venta Semana'!$E$12)/(130) -> 10 | F3: =SUMIFS(Venta!$I$4:$I$365,Venta!$F$4:$F$365,'Venta Semana'!C3,Venta!$B$4:$B$365,'Venta Semana'!$F$12)/(130) -> 16 | G3: =SUMIFS(Venta!$I$4:$I$365,Venta!$F$4:$F$365,'Venta Semana'!C3,Venta!$B$4:$B$365,'Venta Semana'!$G$12)/(130) -> 10 | H3: =SUMIFS(Venta!$I$4:$I$365,Venta!$F$4:$F$365,'Venta Semana'!C3,Venta!$B$4:$B$365,'Venta Semana'!$H$12)/(130) -> 0 | I3: =SUMIFS(Venta!$I$4:$I$365,Venta!$F$4:$F$365,'Venta Semana'!C3,Venta!$B$4:$B$365,'Venta Semana'!$I$12) -> 0 | J3: =SUMIFS(Venta!$I$4:$I$365,Venta!$F$4:$F$365,'Venta Semana'!C3,Venta!$B$4:$B$365,'Venta Semana'!$J$12) -> 0 | K3: =SUMIFS(Venta!$I$4:$I$365,Venta!$F$4:$F$365,'Venta Semana'!C3,Venta!$B$4:$B$365,'Venta Semana'!$K$12) -> 0 | L3: =SUMIFS(Venta!$I$4:$I$365,Venta!$F$4:$F$365,'Venta Semana'!C3,Venta!$B$4:$B$365,'Venta Semana'!$L$12) -> 0 | M3: =SUMIFS(Venta!$I$4:$I$365,Venta!$F$4:$F$365,'Venta Semana'!C3,Venta!$B$4:$B$365,'Venta Semana'!$M$12) -> 0 | N3: =SUM(D3:M3) -> 79
B4: 2 | C4: =Product!C6 -> Pica rico | D4: =SUMIFS(Venta!$I$4:$I$365,Venta!$F$4:$F$365,'Venta Semana'!C4,Venta!$B$4:$B$365,'Venta Semana'!$D$12)/(130) -> 22 | E4: =SUMIFS(Venta!$I$4:$I$365,Venta!$F$4:$F$365,'Venta Semana'!C4,Venta!$B$4:$B$365,'Venta Semana'!$E$12)/(130) -> 16 | F4: =SUMIFS(Venta!$I$4:$I$365,Venta!$F$4:$F$365,'Venta Semana'!C4,Venta!$B$4:$B$365,'Venta Semana'!$F$12)/(130) -> 13 | G4: =SUMIFS(Venta!$I$4:$I$365,Venta!$F$4:$F$365,'Venta Semana'!C4,Venta!$B$4:$B$365,'Venta Semana'!$G$12)/(130) -> 4 | H4: =SUMIFS(Venta!$I$4:$I$365,Venta!$F$4:$F$365,'Venta Semana'!C4,Venta!$B$4:$B$365,'Venta Semana'!$H$12)/(130) -> 0 | I4: =SUMIFS(Venta!$I$4:$I$365,Venta!$F$4:$F$365,'Venta Semana'!C4,Venta!$B$4:$B$365,'Venta Semana'!$I$12) -> 0 | J4: =SUMIFS(Venta!$I$4:$I$365,Venta!$F$4:$F$365,'Venta Semana'!C4,Venta!$B$4:$B$365,'Venta Semana'!$J$12) -> 0 | K4: =SUMIFS(Venta!$I$4:$I$365,Venta!$F$4:$F$365,'Venta Semana'!C4,Venta!$B$4:$B$365,'Venta Semana'!$K$12) -> 0 | L4: =SUMIFS(Venta!$I$4:$I$365,Venta!$F$4:$F$365,'Venta Semana'!C4,Venta!$B$4:$B$365,'Venta Semana'!$L$12) -> 0 | M4: =SUMIFS(Venta!$I$4:$I$365,Venta!$F$4:$F$365,'Venta Semana'!C4,Venta!$B$4:$B$365,'Venta Semana'!$M$12) -> 0 | N4: =SUM(D4:M4) -> 55
B5: 3 | C5: =Product!C7 -> Pica suave | D5: =SUMIFS(Venta!$I$4:$I$365,Venta!$F$4:$F$365,'Venta Semana'!C5,Venta!$B$4:$B$365,'Venta Semana'!$D$12)/(130) -> 15 | E5: =SUMIFS(Venta!$I$4:$I$365,Venta!$F$4:$F$365,'Venta Semana'!C5,Venta!$B$4:$B$365,'Venta Semana'!$E$12)/(130) -> 16 | F5: =SUMIFS(Venta!$I$4:$I$365,Venta!$F$4:$F$365,'Venta Semana'!C5,Venta!$B$4:$B$365,'Venta Semana'!$F$12)/(130) -> 6 | G5: =SUMIFS(Venta!$I$4:$I$365,Venta!$F$4:$F$365,'Venta Semana'!C5,Venta!$B$4:$B$365,'Venta Semana'!$G$12)/(130) -> 3 | H5: =SUMIFS(Venta!$I$4:$I$365,Venta!$F$4:$F$365,'Venta Semana'!C5,Venta!$B$4:$B$365,'Venta Semana'!$H$12)/(130) -> 0 | I5: =SUMIFS(Venta!$I$4:$I$365,Venta!$F$4:$F$365,'Venta Semana'!C5,Venta!$B$4:$B$365,'Venta Semana'!$I$12) -> 0 | J5: =SUMIFS(Venta!$I$4:$I$365,Venta!$F$4:$F$365,'Venta Semana'!C5,Venta!$B$4:$B$365,'Venta Semana'!$J$12) -> 0 | K5: =SUMIFS(Venta!$I$4:$I$365,Venta!$F$4:$F$365,'Venta Semana'!C5,Venta!$B$4:$B$365,'Venta Semana'!$K$12) -> 0 | L5: =SUMIFS(Venta!$I$4:$I$365,Venta!$F$4:$F$365,'Venta Semana'!C5,Venta!$B$4:$B$365,'Venta Semana'!$L$12) -> 0 | M5: =SUMIFS(Venta!$I$4:$I$365,Venta!$F$4:$F$365,'Venta Semana'!C5,Venta!$B$4:$B$365,'Venta Semana'!$M$12) -> 0 | N5: =SUM(D5:M5) -> 40
B6: 4 | C6: =Product!C8 -> Combo | D6: =SUMIFS(Venta!$I$4:$I$365,Venta!$F$4:$F$365,'Venta Semana'!C6,Venta!$B$4:$B$365,'Venta Semana'!$D$12)/(130) -> 0 | E6: =SUMIFS(Venta!$I$4:$I$365,Venta!$F$4:$F$365,'Venta Semana'!C6,Venta!$B$4:$B$365,'Venta Semana'!$E$12)/(130) -> 0 | F6: =SUMIFS(Venta!$I$4:$I$365,Venta!$F$4:$F$365,'Venta Semana'!C6,Venta!$B$4:$B$365,'Venta Semana'!$F$12)/(180) -> 6 | G6: =SUMIFS(Venta!$I$4:$I$365,Venta!$F$4:$F$365,'Venta Semana'!C6,Venta!$B$4:$B$365,'Venta Semana'!$G$12)/(180) -> 8
B7: 5 | C7: =Product!C9 -> pica extremo pequeño | D7: =SUMIFS(Venta!$I$4:$I$365,Venta!$F$4:$F$365,'Venta Semana'!C7,Venta!$B$4:$B$365,'Venta Semana'!$D$12)/(130) -> 0 | E7: =SUMIFS(Venta!$I$4:$I$365,Venta!$F$4:$F$365,'Venta Semana'!C7,Venta!$B$4:$B$365,'Venta Semana'!$E$12)/(130) -> 0 | G7: =SUMIFS(Venta!$I$4:$I$365,Venta!$F$4:$F$365,'Venta Semana'!C7,Venta!$B$4:$B$365,'Venta Semana'!$G$12)/(70) -> 5
B8: 6 | C8: =Product!C10 -> pica rico pequeño | D8: =SUMIFS(Venta!$I$4:$I$365,Venta!$F$4:$F$365,'Venta Semana'!C8,Venta!$B$4:$B$365,'Venta Semana'!$D$12)/(130) -> 0 | E8: =SUMIFS(Venta!$I$4:$I$365,Venta!$F$4:$F$365,'Venta Semana'!C8,Venta!$B$4:$B$365,'Venta Semana'!$E$12)/(130) -> 0 | G8: =SUMIFS(Venta!$I$4:$I$365,Venta!$F$4:$F$365,'Venta Semana'!C8,Venta!$B$4:$B$365,'Venta Semana'!$G$12)/(70) -> 10
C9: Total Venta unidades | D9: =SUM(D3:D5) -> 80 | E9: =SUM(E3:E5) -> 42 | F9: =SUM(F3:F6) -> 41 | G9: =SUM(G3:G8) -> 40 | H9: =SUM(H3:H5) -> 0 | I9: =SUM(I3:I5) -> 0 | J9: =SUM(J3:J5) -> 0 | K9: =SUM(K3:K5) -> 0 | L9: =SUM(L3:L5) -> 0 | M9: =SUM(M3:M5) -> 0 | N9: =SUM(D9:M9) -> 203
B11: INFORME DE VENTAS POR PRODUCTO MES A MES
B12: Item | C12: Producto | D12: semana 3 | E12: semana 4 | F12: semana 5 | G12: semana 6 | H12: semana 7 | I12: semana 8 | J12: semana 9 | K12: semana 10 | L12: semana 11 | M12: semana 12 | N12: Total
B13: 1 | C13: =Product!C5 -> Pica extremo | D13: =SUMIFS(Venta!$I$4:$I$365,Venta!$F$4:$F$365,'Venta Semana'!C13,Venta!$B$4:$B$365,'Venta Semana'!$D$12) -> 5590 | E13: =SUMIFS(Venta!$I$4:$I$365,Venta!$F$4:$F$365,'Venta Semana'!C13,Venta!$B$4:$B$365,'Venta Semana'!$E$12) -> 1300 | F13: =SUMIFS(Venta!$I$4:$I$365,Venta!$F$4:$F$365,'Venta Semana'!C13,Venta!$B$4:$B$365,'Venta Semana'!$F$12) -> 2080 | G13: =SUMIFS(Venta!$I$4:$I$365,Venta!$F$4:$F$365,'Venta Semana'!C13,Venta!$B$4:$B$365,'Venta Semana'!$G$12) -> 1300 | H13: =SUMIFS(Venta!$I$4:$I$365,Venta!$F$4:$F$365,'Venta Semana'!C13,Venta!$B$4:$B$365,'Venta Semana'!$H$12) -> 0 | I13: =SUMIFS(Venta!$I$4:$I$365,Venta!$F$4:$F$365,'Venta Semana'!C13,Venta!$B$4:$B$365,'Venta Semana'!$I$12) -> 0 | J13: =SUMIFS(Venta!$I$4:$I$365,Venta!$F$4:$F$365,'Venta Semana'!C13,Venta!$B$4:$B$365,'Venta Semana'!$J$12) -> 0 | K13: =SUMIFS(Venta!$I$4:$I$365,Venta!$F$4:$F$365,'Venta Semana'!C13,Venta!$B$4:$B$365,'Venta Semana'!$K$12) -> 0 | L13: =SUMIFS(Venta!$I$4:$I$365,Venta!$F$4:$F$365,'Venta Semana'!C13,Venta!$B$4:$B$365,'Venta Semana'!$L$12) -> 0 | M13: =SUMIFS(Venta!$I$4:$I$365,Venta!$F$4:$F$365,'Venta Semana'!C13,Venta!$B$4:$B$365,'Venta Semana'!$M$12) -> 0 | N13: =SUM(D13:M13) -> 10270
B14: 2 | C14: =Product!C6 -> Pica rico | D14: =SUMIFS(Venta!$I$4:$I$365,Venta!$F$4:$F$365,'Venta Semana'!C14,Venta!$B$4:$B$365,'Venta Semana'!$D$12) -> 2860 | E14: =SUMIFS(Venta!$I$4:$I$365,Venta!$F$4:$F$365,'Venta Semana'!C14,Venta!$B$4:$B$365,'Venta Semana'!$E$12) -> 2080 | F14: =SUMIFS(Venta!$I$4:$I$365,Venta!$F$4:$F$365,'Venta Semana'!C14,Venta!$B$4:$B$365,'Venta Semana'!$F$12) -> 1690 | G14: =SUMIFS(Venta!$I$4:$I$365,Venta!$F$4:$F$365,'Venta Semana'!C14,Venta!$B$4:$B$365,'Venta Semana'!$G$12) -> 520 | H14: =SUMIFS(Venta!$I$4:$I$365,Venta!$F$4:$F$365,'Venta Semana'!C14,Venta!$B$4:$B$365,'Venta Semana'!$H$12) -> 0 | I14: =SUMIFS(Venta!$I$4:$I$365,Venta!$F$4:$F$365,'Venta Semana'!C14,Venta!$B$4:$B$365,'Venta Semana'!$I$12) -> 0 | J14: =SUMIFS(Venta!$I$4:$I$365,Venta!$F$4:$F$365,'Venta Semana'!C14,Venta!$B$4:$B$365,'Venta Semana'!$J$12) -> 0 | K14: =SUMIFS(Venta!$I$4:$I$365,Venta!$F$4:$F$365,'Venta Semana'!C14,Venta!$B$4:$B$365,'Venta Semana'!$K$12) -> 0 | L14: =SUMIFS(Venta!$I$4:$I$365,Venta!$F$4:$F$365,'Venta Semana'!C14,Venta!$B$4:$B$365,'Venta Semana'!$L$12) -> 0 | M14: =SUMIFS(Venta!$I$4:$I$365,Venta!$F$4:$F$365,'Venta Semana'!C14,Venta!$B$4:$B$365,'Venta Semana'!$M$12) -> 0 | N14: =SUM(D14:M14) -> 7150
B15: 3 | C15: =Product!C7 -> Pica suave | D15: =SUMIFS(Venta!$I$4:$I$365,Venta!$F$4:$F$365,'Venta Semana'!C15,Venta!$B$4:$B$365,'Venta Semana'!$D$12) -> 1950 | E15: =SUMIFS(Venta!$I$4:$I$365,Venta!$F$4:$F$365,'Venta Semana'!C15,Venta!$B$4:$B$365,'Venta Semana'!$E$12) -> 2080 | F15: =SUMIFS(Venta!$I$4:$I$365,Venta!$F$4:$F$365,'Venta Semana'!C15,Venta!$B$4:$B$365,'Venta Semana'!$F$12) -> 780 | G15: =SUMIFS(Venta!$I$4:$I$365,Venta!$F$4:$F$365,'Venta Semana'!C15,Venta!$B$4:$B$365,'Venta Semana'!$G$12) -> 390 | H15: =SUMIFS(Venta!$I$4:$I$365,Venta!$F$4:$F$365,'Venta Semana'!C15,Venta!$B$4:$B$365,'Venta Semana'!$H$12) -> 0 | I15: =SUMIFS(Venta!$I$4:$I$365,Venta!$F$4:$F$365,'Venta Semana'!C15,Venta!$B$4:$B$365,'Venta Semana'!$I$12) -> 0 | J15: =SUMIFS(Venta!$I$4:$I$365,Venta!$F$4:$F$365,'Venta Semana'!C15,Venta!$B$4:$B$365,'Venta Semana'!$J$12) -> 0 | K15: =SUMIFS(Venta!$I$4:$I$365,Venta!$F$4:$F$365,'Venta Semana'!C15,Venta!$B$4:$B$365,'Venta Semana'!$K$12) -> 0 | L15: =SUMIFS(Venta!$I$4:$I$365,Venta!$F$4:$F$365,'Venta Semana'!C15,Venta!$B$4:$B$365,'Venta Semana'!$L$12) -> 0 | M15: =SUMIFS(Venta!$I$4:$I$365,Venta!$F$4:$F$365,'Venta Semana'!C15,Venta!$B$4:$B$365,'Venta Semana'!$M$12) -> 0 | N15: =SUM(D15:M15) -> 5200
B16: 4 | C16: =Product!C8 -> Combo | D16: =SUMIFS(Venta!$I$4:$I$365,Venta!$F$4:$F$365,'Venta Semana'!C16,Venta!$B$4:$B$365,'Venta Semana'!$D$12) -> 0 | E16: =SUMIFS(Venta!$I$4:$I$365,Venta!$F$4:$F$365,'Venta Semana'!C16,Venta!$B$4:$B$365,'Venta Semana'!$E$12) -> 0 | F16: =SUMIFS(Venta!$I$4:$I$365,Venta!$F$4:$F$365,'Venta Semana'!C16,Venta!$B$4:$B$365,'Venta Semana'!$F$12) -> 1080 | G16: =SUMIFS(Venta!$I$4:$I$365,Venta!$F$4:$F$365,'Venta Semana'!C16,Venta!$B$4:$B$365,'Venta Semana'!$G$12) -> 1440 | H16: =SUMIFS(Venta!$I$4:$I$365,Venta!$F$4:$F$365,'Venta Semana'!C16,Venta!$B$4:$B$365,'Venta Semana'!$H$12) -> 0 | I16: =SUMIFS(Venta!$I$4:$I$365,Venta!$F$4:$F$365,'Venta Semana'!C16,Venta!$B$4:$B$365,'Venta Semana'!$I$12) -> 0 | J16: =SUMIFS(Venta!$I$4:$I$365,Venta!$F$4:$F$365,'Venta Semana'!C16,Venta!$B$4:$B$365,'Venta Semana'!$J$12) -> 0 | K16: =SUMIFS(Venta!$I$4:$I$365,Venta!$F$4:$F$365,'Venta Semana'!C16,Venta!$B$4:$B$365,'Venta Semana'!$K$12) -> 0 | L16: =SUMIFS(Venta!$I$4:$I$365,Venta!$F$4:$F$365,'Venta Semana'!C16,Venta!$B$4:$B$365,'Venta Semana'!$L$12) -> 0 | M16: =SUMIFS(Venta!$I$4:$I$365,Venta!$F$4:$F$365,'Venta Semana'!C16,Venta!$B$4:$B$365,'Venta Semana'!$M$12) -> 0
B17: 5 | C17: =Product!C9 -> pica extremo pequeño | D17: =SUMIFS(Venta!$I$4:$I$365,Venta!$F$4:$F$365,'Venta Semana'!C17,Venta!$B$4:$B$365,'Venta Semana'!$D$12) -> 0 | E17: =SUMIFS(Venta!$I$4:$I$365,Venta!$F$4:$F$365,'Venta Semana'!C17,Venta!$B$4:$B$365,'Venta Semana'!$E$12) -> 0 | F17: =SUMIFS(Venta!$I$4:$I$365,Venta!$F$4:$F$365,'Venta Semana'!C17,Venta!$B$4:$B$365,'Venta Semana'!$F$12) -> 0 | G17: =SUMIFS(Venta!$I$4:$I$365,Venta!$F$4:$F$365,'Venta Semana'!C17,Venta!$B$4:$B$365,'Venta Semana'!$G$12) -> 350 | H17: =SUMIFS(Venta!$I$4:$I$365,Venta!$F$4:$F$365,'Venta Semana'!C17,Venta!$B$4:$B$365,'Venta Semana'!$H$12) -> 0 | I17: =SUMIFS(Venta!$I$4:$I$365,Venta!$F$4:$F$365,'Venta Semana'!C17,Venta!$B$4:$B$365,'Venta Semana'!$I$12) -> 0 | J17: =SUMIFS(Venta!$I$4:$I$365,Venta!$F$4:$F$365,'Venta Semana'!C17,Venta!$B$4:$B$365,'Venta Semana'!$J$12) -> 0 | K17: =SUMIFS(Venta!$I$4:$I$365,Venta!$F$4:$F$365,'Venta Semana'!C17,Venta!$B$4:$B$365,'Venta Semana'!$K$12) -> 0 | L17: =SUMIFS(Venta!$I$4:$I$365,Venta!$F$4:$F$365,'Venta Semana'!C17,Venta!$B$4:$B$365,'Venta Semana'!$L$12) -> 0 | M17: =SUMIFS(Venta!$I$4:$I$365,Venta!$F$4:$F$365,'Venta Semana'!C17,Venta!$B$4:$B$365,'Venta Semana'!$M$12) -> 0
B18: 6 | C18: =Product!C10 -> pica rico pequeño | D18: =SUMIFS(Venta!$I$4:$I$365,Venta!$F$4:$F$365,'Venta Semana'!C18,Venta!$B$4:$B$365,'Venta Semana'!$D$12) -> 0 | E18: =SUMIFS(Venta!$I$4:$I$365,Venta!$F$4:$F$365,'Venta Semana'!C18,Venta!$B$4:$B$365,'Venta Semana'!$E$12) -> 0 | F18: =SUMIFS(Venta!$I$4:$I$365,Venta!$F$4:$F$365,'Venta Semana'!C18,Venta!$B$4:$B$365,'Venta Semana'!$F$12) -> 0 | G18: =SUMIFS(Venta!$I$4:$I$365,Venta!$F$4:$F$365,'Venta Semana'!C18,Venta!$B$4:$B$365,'Venta Semana'!$G$12) -> 700 | H18: =SUMIFS(Venta!$I$4:$I$365,Venta!$F$4:$F$365,'Venta Semana'!C18,Venta!$B$4:$B$365,'Venta Semana'!$H$12) -> 0 | I18: =SUMIFS(Venta!$I$4:$I$365,Venta!$F$4:$F$365,'Venta Semana'!C18,Venta!$B$4:$B$365,'Venta Semana'!$I$12) -> 0 | J18: =SUMIFS(Venta!$I$4:$I$365,Venta!$F$4:$F$365,'Venta Semana'!C18,Venta!$B$4:$B$365,'Venta Semana'!$J$12) -> 0 | K18: =SUMIFS(Venta!$I$4:$I$365,Venta!$F$4:$F$365,'Venta Semana'!C18,Venta!$B$4:$B$365,'Venta Semana'!$K$12) -> 0 | L18: =SUMIFS(Venta!$I$4:$I$365,Venta!$F$4:$F$365,'Venta Semana'!C18,Venta!$B$4:$B$365,'Venta Semana'!$L$12) -> 0 | M18: =SUMIFS(Venta!$I$4:$I$365,Venta!$F$4:$F$365,'Venta Semana'!C18,Venta!$B$4:$B$365,'Venta Semana'!$M$12) -> 0
C19: Total venta | D19: =SUM(D13:D15) -> 10400 | E19: =SUM(E13:E15) -> 5460 | F19: =SUM(F13:F16) -> 5630 | G19: =SUM(G13:G18) -> 4700 | H19: =SUM(H13:H15) -> 0 | I19: =SUM(I13:I15) -> 0 | J19: =SUM(J13:J15) -> 0 | K19: =SUM(K13:K15) -> 0 | L19: =SUM(L13:L15) -> 0 | M19: =SUM(M13:M15) -> 0 | N19: =SUM(D19:M19) -> 26190

Sheet Venta por Vendedor
B2: INFORME DE VENTAS POR VENDEDOR
B3: Semana 3
B4: Vendedor | C4: pica extremo | D4: pica rico | E4: pica suave | I4: SUBTOTAL | J4: TOTAL
B5: Alexandra | C5: 6 | D5: 6 | E5: 5 | I5: =SUM(C5:E5) -> 17 | J5: =SUM(I5:I10) -> 51
B6: Gerson | C6: 0 | D6: =Venta!H34 -> 1 | E6: 0 | I6: =SUM(C6:E6) -> 1
B7: Keren | C7: =Venta!H10 -> 1 | D7: 0 | E7: 2 | I7: =SUM(C7:E7) -> 3
B8: Nicolle | C8: 13 | D8: 4 | E8: 3 | I8: =SUM(C8:E8) -> 20 | K8: NOTA: EN LA SEMANA 3 NO SE ESTAN TOMANDO EN CUENTA LOS VENDIDOS 29 EN LANZAMIENTOS SOLO LOS INDIVIDUALES
B9: Sthepany | C9: =Venta!H38 -> 5 | D9: 1 | I9: =SUM(C9:E9) -> 6
B10: Tomas | C10: 3 | E10: 1 | I10: =SUM(C10:E10) -> 4
B11: Semana 4
B12: Vendedor | C12: pica extremo | D12: pica rico | E12: pica suave | I12: SUBTOTAL | J12: TOTAL
B13: Alexandra | I13: =SUM(C13:E13) -> 0 | J13: =SUM(I13:I18) -> 42
B14: Gerson | C14: 2 | D14: 3 | E14: 2 | I14: =SUM(C14:E14) -> 7
B15: Keren | C15: 2 | D15: 3 | E15: 6 | I15: =SUM(C15:E15) -> 11
B16: Nicolle | C16: 1 | E16: 1 | I16: =SUM(C16:E16) -> 2
B17: Sthepany | C17: 3 | D17: 2 | E17: 1 | I17: =SUM(C17:E17) -> 6
B18: Tomas | C18: 2 | D18: 8 | E18: 6 | I18: =SUM(C18:E18) -> 16
B19: SEMANA 5
B20: Vendedor | C20: pica extremo | D20: pica rico | E20: pica suave | H20: SUB UNIDADES | I20: COMBO | J20: TOTAL
B21: Alexandra | C21: 5 | D21: 6 | E21: 3 | H21: =SUM(C21:E21) -> 14
B22: Gerson | C22: 2 | D22: 3 | E22: 1 | H22: =SUM(C22:K22) -> 9 | I22: 3
B23: Keren | D23: 3 | E23: 1 | H23: =SUM(C23:K23) -> 5 | I23: 1
B24: Nicolle | E24: 1 | H24: =SUM(C24:K24) -> 3 | I24: 2
B25: Sthepany | C25: 3 | D25: 1 | H25: =SUM(C25:K25) -> 4
B26: Tomas | C26: 6 | H26: =SUM(C26:K26) -> 6
B27: TOTAL | C27: =SUM(C21:C26) -> 16 | D27: =SUM(D21:D26) -> 13 | E27: =SUM(E21:E26) -> 6 | H27: =SUM(H21:H26) -> 16 | I27: =SUM(I21:I26) -> 6 | J27: =SUM(I27+H27) -> 41
B28: SEMANA 6
B29: Vendedor | C29: pica extremo | D29: pica rico | E29: pica suave | F29: Extremo pequeño | G29: Rico pequeño | H29: Combo | I29: SUBTOTAL | J29: TOTAL
B30: Alexandra | C30: 2 | E30: 2 | I30: =SUM(C30:G30) -> 4
B31: Gerson | H31: 1 | I31: =SUM(C31:G31) -> 0
B32: Keren | H32: 2 | I32: =SUM(C32:G32) -> 0
B33: Nicolle | C33: 3 | H33: 2 | I33: =SUM(C33:G33) -> 3
B34: Sthepany | D34: 2 | H34: 1 | I34: =SUM(C34:G34) -> 2
B35: Tomas | C35: 1 | F35: 5 | G35: 10 | H35: 2 | I35: =SUM(C35:G35) -> 16
B36: TOTAL | C36: =SUM(C30:C35) -> 6 | D36: =SUM(D30:D35) -> 2 | E36: =SUM(E30:E35) -> 2 | H36: =SUM(H30:H35) -> 8 | I36: =SUM(I30:I35) -> 25 | J36: =SUM(I36+H36) -> 33
B37: SEMANA 7
B38: Vendedor | C38: pica extremo | D38: pica rico | E38: pica suave | F38: Extremo pequeño | G38: Rico pequeño | H38: Combo | I38: Subtotal | J38: TOTAL
B39: Alexandra
B40: Gerson
B41: Keren
...

Sheet Base de datos clientes
A1: ID | B1: Nombre | C1: Telefono | D1: Profesion | E1: Empresa | F1: Ciudad | G1: Compras | H1: Estado
A2: CLI-001 | B2: Abraham Figueroa | C2: 94072826 | D2: Docente | E2: UNAH | F2: Tegucigalpa | H2: Activo
A3: CLI-002 | B3: Activacion Televicentro | C3: 92263088 | D3: Estudiante | E3: Independiente | F3: Tegucigalpa | H3: Activo
A4: CLI-003 | B4: Alex Maradiaga | C4: 8959-4167 | D4: Licenciado | E4: Grupo Flores | F4: Tegucigalpa | H4: Activo
A5: CLI-004 | B5: Allan Cruz | C5: 9693-0988 | D5: Docente | E5: Grupo Flores | F5: Tegucigalpa | H5: Activo
A6: CLI-005 | B6: Ana Suazo | C6: 8959-4169 | D6: Licenciado | E6: Empresa Privada | F6: Tegucigalpa | H6: Activo
A7: CLI-006 | B7: Anny Nicolle | C7: 9470 6313 | D7: Ingeniero | E7: UNAH | F7: Tegucigalpa | H7: Activo
A8: CLI-007 | B8: Bayron Robles | C8: 3340-7611 | D8: Ingeniero | E8: Empresa Privada | F8: Tegucigalpa | H8: Activo
A9: CLI-008 | B9: Brian Edgardo funes | C9: 88916581 | D9: Vendedor | E9: Claro | F9: Tegucigalpa | H9: Activo
A10: CLI-009 | B10: Bryan Christian Cruz | C10: 94428006 | D10: Licenciado | E10: UNAH | F10: Tegucigalpa | H10: Activo
A11: CLI-010 | B11: Bryan Oneal | C11: 9849-5689 | D11: Estudiante | E11: Independiente | F11: Tegucigalpa | H11: Activo
A12: CLI-011 | B12: Camila Rosales | C12: 9668-7434 | D12: Administrador | E12: Indufesa | F12: Tegucigalpa | H12: Activo
A13: CLI-012 | B13: Carlos Fernando | C13: 8852-9078 | D13: Licenciado | E13: Independiente | F13: Tegucigalpa | H13: Activo
A14: CLI-013 | B14: Carlos Josiel Hernandez | C14: 99334283 | D14: Licenciado | E14: UNAH | F14: Tegucigalpa | G14: 4 | H14: Activo
A15: CLI-014 | B15: Cesar Cruz | C15: 99909477 | D15: Licenciado | E15: Indufesa | F15: Tegucigalpa | H15: Activo
A16: CLI-015 | B16: Cristhian Israel | C16: 8794-6911 | D16: Contador | E16: Televicentro | F16: Tegucigalpa | H16: Activo
A17: CLI-016 | B17: Cristian Padilla | C17: 9203-9396 | D17: Licenciado | E17: UNAH | F17: Tegucigalpa | H17: Activo
A18: CLI-017 | B18: Daniel Isaac | C18: 89723363 | D18: Contador | E18: Indufesa | F18: Tegucigalpa | H18: Activo
A19: CLI-018 | B19: Daphne Naomi Ordoñez Martinez | C19: 9693-0986 | D19: Estudiante | E19: Empresa Privada | F19: Tegucigalpa | H19: Activo
A20: CLI-019 | B20: David Castillo | C20: 98805732 | D20: Licenciado | E20: UNAH | F20: Tegucigalpa | H20: Activo
A21: CLI-020 | B21: David Josue Gomez Nuñez | C21: 9469 6313 | D21: Estudiante | E21: Televicentro | F21: Tegucigalpa | H21: Activo
A22: CLI-021 | B22: Diana Flores | C22: 99909481 | D22: Estudiante | E22: Grupo Flores | F22: Tegucigalpa | H22: Activo
A23: CLI-022 | B23: Dilcia UNAH | C23: 9468 6313 | D23: Licenciado | E23: UNAH | F23: Tegucigalpa | H23: Activo
A24: CLI-023 | B24: Dionicio Indufesa | C24: 3292-7698 | D24: Docente | E24: Grupo Flores | F24: Tegucigalpa | H24: Activo
A25: CLI-024 | B25: Emely G. negocios | C25: 9668-7436 | D25: Vendedor | E25: Indufesa | F25: Tegucigalpa | H25: Activo
A26: CLI-025 | B26: Erika Dayana | C26: 8794-6910 | D26: Estudiante | E26: Estudiante | F26: Tegucigalpa | H26: Activo
A27: CLI-026 | B27: Estefany Meza | C27: 94652225 | D27: Administrador | E27: Empresa Privada | F27: Tegucigalpa | H27: Activo
A28: CLI-027 | B28: Evelyn Andino | C28: 3292-7695 | D28: Indepediente | F28: Tegucigalpa | H28: Activo
A29: CLI-028 | B29: Exon Sierra | C29: 8794-6912 | D29: Administrador | E29: Televicentro | F29: Tegucigalpa | H29: Activo
A30: CLI-029 | B30: Fabiola Romero | C30: 96970002 | D30: Docente | E30: UNAH | F30: Tegucigalpa | H30: Activo
A31: CLI-030 | B31: Fabricio Alex | C31: 93518096 | D31: Ingeniero | E31: Estudiante | F31: Tegucigalpa | H31: Activo
A32: CLI-031 | B32: Fanys Moreno | C32: 33647571 | D32: Licenciado | E32: Empresa Privada | F32: Tegucigalpa | H32: Activo
A33: CLI-032 | B33: Fernando Duarte | C33: 89417578 | D33: Docente | E33: Estudiante | F33: Tegucigalpa | H33: Activo
A34: CLI-033 | B34: Francisco Abularach | C34: 94546478 | D34: Gerente de ventas | E34: Indufesa | F34: Tegucigalpa | H34: Activo
A35: CLI-034 | B35: Franklin Paredes | C35: 99909478 | D35: Estudiante | E35: Estudiante | F35: Tegucigalpa | H35: Activo
A36: CLI-035 | B36: Gerson Sevilla | C36: 3340-7612 | D36: Licenciado | E36: Indufesa | F36: Tegucigalpa | H36: Activo
A37: CLI-036 | B37: Gladis Esther Arguijo Matute | C37: 9668-7433 | D37: Docente | E37: UNAH | F37: Tegucigalpa | H37: Activo
A38: CLI-037 | B38: Gracia Maria | C38: 9203-9397 | D38: Estudiante | E38: Independiente | F38: Tegucigalpa | H38: Activo
A39: CLI-038 | B39: Helen Perez | C39: 32487353 | D39: Contador | E39: Empresa Privada | F39: Tegucigalpa | H39: Activo
A40: CLI-039 | B40: Hever Perdomo | C40: 33323464 | D40: Contador | E40: Televicentro | F40: Tegucigalpa | H40: Activo
...

Sheet Plan de ventas
A1: PLAN DE VENTAS PIKAZO
A2: SEMANA 1 | D2: SEMANA 2
A3: Actividad | B3: Estrategias de venta | C3: Meta de venta | D3: Actividad | E3: Estrategias de venta | F3: Meta de venta
A4: Lanzamiento del producto | B4: Realizar degustaciones de carne acompañada con salsa PIKA-ZO. | C4: Alcanzar una meta de 60 unidades vendidas durante la semana. | D4: Posicionamiento comercial | E4: 1. Cada integrante del grupo andar muestras de botes pequeños de las 3 intensidades para poder dar a degustar a los prospecto clientes | F4: 8 chiles picantes por vendedor
B5: Explicar las características, beneficios y presentación del producto. | E5: 2. Promocion de un 10% al repostear un post de nuestras redes sociales | F5: Meta total de la semana de 48 chiles picantes
B6: Incentivar a los asistentes a seguir las redes sociales de la marca. | E6: 3.Gestionar la participación en Canal 5 para promocionar el producto.
B7: Registrar posibles clientes interesados.
